Workbook

Sheet Status
A1: generated_utc | B1: coverage_end | C1: last_complete_year | D1: frozen_history_end | E1: charts_built_for_year | F1: expected_refresh_days | G1: w1 | H1: w2 | I1: w3 | J1: w4 | K1: w5 | L1: w6 | M1: w7 | N1: w8 | O1: health_state | P1: health_note | Q1: health_tabs
A2: NOT REFRESHED | B2: NOT REFRESHED | C2: 2025 | D2: 2025 | E2: 2025 | F2: 10 | G2: 2019 | H2: 2020 | I2: 2021 | J2: 2022 | K2: 2023 | L2: 2024 | M2: 2025 | N2: 2026 | O2: ok
A4: Power Price Data
A5: European hourly power prices — Germany, Spain, Portugal, France, Italy. Source: ENTSO-E Transparency Platform.
A7: =IF(ISERROR(DATEVALUE(LEFT($A$2,10))),"!! NOT REFRESHED - this file is showing built-in preview data, not live data. Close it, re-open, and choose Enable Content when Excel asks about data connections. If that does not fix it, the network is blocking GitHub.","")
A8: =IF(IFERROR(AND(ISNUMBER($F$2),(TODAY()-DATEVALUE(LEFT($A$2,10)))>$F$2),FALSE),"!! STALE DATA - the refresh has not run for "&TEXT(TODAY()-DATEVALUE(LEFT($A$2,10)),"0")&" days. Figures may be out of date.","")
A9: =IF(($O$2="stale-series"),"!! ONE SERIES CAME FROM STORED DATA - "&$P$2&". Every other figure here is current, and a repair run replaces it within hours."&IF($Q$2<>""," Read these tabs with care until it does: "&$Q$2&".",""),"")
A10: =IF(OR(IFERROR(AND(ISNUMBER($F$2),(TODAY()-DATEVALUE(LEFT($A$2,10)))>$F$2),FALSE),($O$2="stale-series")),"ACTION: nothing is wrong with this file, and the figures above are the last ones published. Open "&$A$42&" and press Start a refresh. That needs no repository access and no special software. The next automatic attempt is "&TEXT(IF(DAY(TODAY())<2,DATE(YEAR(TODAY()),MONTH(TODAY()),2),IF(DAY(TODAY())<10,DATE(YEAR(TODAY()),MONTH(TODAY()),10),IF(DAY(TODAY())<18,DATE(YEAR(TODAY()),MONTH(TODAY()),18),IF(DAY(TODAY())<26,DATE(YEAR(TODAY()),MONTH(TODAY()),26),DATE(YEAR(TODAY()),MONTH(TODAY())+1,2))))),"d mmm")&".","")
A11: =IF(ISERROR(DATEVALUE(LEFT($A$2,10))),"Last refreshed: UNKNOWN - not refreshed yet this session.","Last refreshed "&LEFT($A$2,10)&" ("&TEXT(TODAY()-DATEVALUE(LEFT($A$2,10)),"0")&" days ago). Data through "&$B$2&".")
A12: =IF(OR(ISERROR(DATEVALUE(LEFT($A$2,10))),IFERROR(AND(ISNUMBER($F$2),(TODAY()-DATEVALUE(LEFT($A$2,10)))>$F$2),FALSE),($O$2="stale-series")),"","OK - data is current and the charts are up to date.")
A13: ="The next automatic refresh is due "&TEXT(IF(DAY(TODAY())<2,DATE(YEAR(TODAY()),MONTH(TODAY()),2),IF(DAY(TODAY())<10,DATE(YEAR(TODAY()),MONTH(TODAY()),10),IF(DAY(TODAY())<18,DATE(YEAR(TODAY()),MONTH(TODAY()),18),IF(DAY(TODAY())<26,DATE(YEAR(TODAY()),MONTH(TODAY()),26),DATE(YEAR(TODAY()),MONTH(TODAY())+1,2))))),"dddd d mmmm")&" (the 2nd, 10th, 18th and 26th of each month)."
A14: THIS FILE
A15: Pulled live data | B15: =IF(ISERROR(DATEVALUE(LEFT($A$2,10))),"NO - showing built-in preview data","YES - pulled when you opened this file")
A16: How it updates | B16: Automatically, on open. Nothing to press.
A18: THE DATA
A19: Published | B19: =IF(ISERROR(DATEVALUE(LEFT($A$2,10))),"unknown",LEFT($A$2,10)&" ("&TEXT(TODAY()-DATEVALUE(LEFT($A$2,10)),"0")&" days ago)")
A20: Prices run to | B20: =$B$2
A21: Next published | B21: =TEXT(IF(DAY(TODAY())<2,DATE(YEAR(TODAY()),MONTH(TODAY()),2),IF(DAY(TODAY())<10,DATE(YEAR(TODAY()),MONTH(TODAY()),10),IF(DAY(TODAY())<18,DATE(YEAR(TODAY()),MONTH(TODAY()),18),IF(DAY(TODAY())<26,DATE(YEAR(TODAY()),MONTH(TODAY()),26),DATE(YEAR(TODAY()),MONTH(TODAY())+1,2))))),"d mmm yyyy")
A22: Warn if none for | B22: =$F$2&" days"
A24: REFERENCE
A25: Last complete year | B25: =$C$2
A26: Chart year window | B26: =$G$2&" to "&$M$2
A27: Frozen history ends | B27: =$D$2
A29: WHAT YOU NEED TO DO
A30: NOTHING — not monthly, not yearly, not ever.
A31: The data refreshes itself every time you open this file.
A32: A job re-publishes it on the 2nd, 10th, 18th and 26th.
A33: You never need to download a replacement for this workbook.
A35: WHEN A NEW CALENDAR YEAR STARTS — still nothing.
A36: Every chart here rolls forward on its own. In January the newly
A37: completed year appears by itself, and the oldest drops off, so each
A38: exhibit always shows the same span of recent years.
A39: This is the one thing that used to need a person, and no longer does.
A41: Check that the data is current, or look at the source figures:
A42: https://power-price-data.fredhill.workers.dev
... A50: typed there is overwritten on the next refresh.
A52: Tab | B52: Loads from
A53: Fig1_PriceSD | B53: https://raw.githubusercontent.com/Power-Utilities-team/power-price-data/main/published/charts/fig1_price_sd.csv
A54: Fig2_Intraday | B54: https://raw.githubusercontent.com/Power-Utilities-team/power-price-data/main/published/charts/fig2_intraday_indexed.csv
A55: Fig3_NegHours | B55: https://raw.githubusercontent.com/Power-Utilities-team/power-price-data/main/published/charts/fig3_neg_hours_annual.csv
...

Sheet Charts
A1: Fig 1 — Price volatility: annual standard deviation of hourly day-ahead price (€/MWh) | L1: Fig 2 — Intraday price shape by year, indexed to daily mean = 1 (Germany)
A21: Fig 3 — Negative-price hours per year, by country | L21: Fig 3 — Cumulative near-negative-price hours through the year (Germany)
A41: Fig 4 — Price duration curves by year (Portugal) | L41: Fig 5 — Capture price vs baseload by technology (Germany)
A61: ="Fig 6 — Daily minimum vs maximum price (Germany, "&Status!$C$2&")" -> Fig 6 — Daily minimum vs maximum price (Germany, 2025) | L61: ="Fig 7 — Intraday generation mix and price (Portugal, "&Status!$C$2&")" -> Fig 7 — Intraday generation mix and price (Portugal, 2025)
A81: Fig 9 — Installed generation capacity by technology (Germany)
L81: Spain — intraday price shape, indexed to daily mean
A101: Germany — intraday price shape (€/MWh), the deepening 'duck' belly
L101: Portugal — capture price vs baseload by technology
A121: Spain — cumulative near-negative-price hours through the year
A141: France — capture price vs baseload by technology
L141: Spain — capture price vs baseload by technology
A161: Italy — capture price vs baseload by technology
L161: France — intraday price shape, indexed to daily mean
A181: Fig 9 — Installed generation capacity by technology (Spain)
L181: Fig 9 — Installed generation capacity by technology (Portugal)
A201: Fig 9 — Installed generation capacity by technology (France)
L201: Fig 9 — Installed generation capacity by technology (Italy)
A221: Portugal — intraday price shape, indexed to daily mean
L221: Italy — intraday price shape, indexed to daily mean
A241: Portugal — cumulative near-negative-price hours through the year
L241: France — cumulative near-negative-price hours through the year
A261: Italy — cumulative near-negative-price hours through the year
L261: Germany — Onshore wind: capture as % of base price, by month (one line per year)
A281: Germany — Solar: capture as % of base price, by month (one line per year)
L281: Germany — Lignite: capture as % of base price, by month (one line per year)
A301: Germany — Gas: capture as % of base price, by month (one line per year)
L301: Germany — Biomass: capture as % of base price, by month (one line per year)
A321: Germany — Hard coal: capture as % of base price, by month (one line per year)
L321: Germany — Hydro reservoir: capture as % of base price, by month (one line per year)
A341: Spain — Onshore wind: capture as % of base price, by month (one line per year)
L341: Spain — Solar: capture as % of base price, by month (one line per year)
A361: Spain — Nuclear: capture as % of base price, by month (one line per year)
L361: Spain — Gas: capture as % of base price, by month (one line per year)
A381: Spain — Hydro reservoir: capture as % of base price, by month (one line per year)
L381: Spain — Hydro pumped (production): capture as % of base price, by month (one line per year)
A401: Portugal — Onshore wind: capture as % of base price, by month (one line per year)
L401: Portugal — Hydro run-of-river: capture as % of base price, by month (one line per year)
A421: Portugal — Gas: capture as % of base price, by month (one line per year)
L421: Portugal — Hydro pumped (production): capture as % of base price, by month (one line per year)
A441: Portugal — Solar: capture as % of base price, by month (one line per year)
...

Sheet Fig1_PriceSD
A1: year | B1: Germany | C1: Spain | D1: Portugal | E1: France | F1: Italy
A2: 2019 | B2: 15.52 | C2: 10.88 | D2: 10.81 | E2: 14.02 | F2: 12.67
A3: 2020 | B3: 17.5 | C3: 11.42 | D3: 11.26 | E3: 16.11 | F3: 14.63
A4: 2021 | B4: 73.68 | C4: 74.71 | D4: 74.7 | E4: 84.31 | F4: 81.08
A5: 2022 | B5: 142.82 | C5: 69.46 | D5: 69.13 | E5: 145.84 | F5: 133.15
A6: 2023 | B6: 47.58 | C6: 41.34 | D6: 39.93 | E6: 45.53 | F6: 35.59
A7: 2024 | B7: 52.73 | C7: 45.94 | D7: 45.57 | E7: 40.66 | F7: 29.66
A8: 2025 | B8: 52.09 | C8: 47.61 | D8: 46.44 | E8: 46.38 | F8: 29.69
A9: 2026 | B9: 66.6 | C9: 68.97 | D9: 69.05 | E9: 67.19 | F9: 47.48
A10: 2027
A11: 2028
A12: 2029
A13: 2030
A14: 2031
A15: 2032
A16: 2033
A17: 2034
A18: 2035

Sheet Fig2_Intraday
A1: hour_utc | B1: DE_2019 | C1: DE_2020 | D1: DE_2021 | E1: DE_2022 | F1: DE_2023 | G1: DE_2024 | H1: DE_2025 | I1: DE_2026 | J1: DE_2027 | K1: DE_2028 | L1: DE_2029 | M1: DE_2030 | N1: DE_2031 | O1: DE_2032 | P1: DE_2033 | Q1: DE_2034 | R1: DE_2035 | S1: ES_2019 | T1: ES_2020 | U1: ES_2021 | V1: ES_2022 | W1: ES_2023 | X1: ES_2024 | Y1: ES_2025 | Z1: ES_2026 | AA1: ES_2027 | AB1: ES_2028 | AC1: ES_2029 | AD1: ES_2030 | AE1: ES_2031 | AF1: ES_2032 | AG1: ES_2033 | AH1: ES_2034 | AI1: ES_2035 | AJ1: PT_2019 | AK1: PT_2020 | AL1: PT_2021 | AM1: PT_2022 | AN1: PT_2023 | AO1: PT_2024 | AP1: PT_2025 | AQ1: PT_2026 | AR1: PT_2027 | AS1: PT_2028 | AT1: PT_2029 | AU1: PT_2030 | AV1: PT_2031 | AW1: PT_2032 | AX1: PT_2033 | AY1: PT_2034 | AZ1: PT_2035 | BA1: FR_2019 | BB1: FR_2020 | BC1: FR_2021 | BD1: FR_2022 | BE1: FR_2023 | BF1: FR_2024 | BG1: FR_2025 | BH1: FR_2026 | BI1: FR_2027 | BJ1: FR_2028 | BK1: FR_2029 | BL1: FR_2030 | BM1: FR_2031 | BN1: FR_2032 | BO1: FR_2033 | BP1: FR_2034 | BQ1: FR_2035 | BR1: IT_2019 | BS1: IT_2020 | BT1: IT_2021 | BU1: IT_2022 | BV1: IT_2023 | BW1: IT_2024 | BX1: IT_2025 | BY1: IT_2026 | BZ1: IT_2027 | CA1: IT_2028 | CB1: IT_2029 | CC1: IT_2030 | CD1: IT_2031 | CE1: IT_2032 | CF1: IT_2033 | CG1: IT_2034 | CH1: IT_2035
A2: 0 | B2: 0.7721 | C2: 0.7574 | D2: 0.7706 | E2: 0.8372 | F2: 0.8402 | G2: 0.8513 | H2: 0.9172 | I2: 1.0362 | S2: 0.9061 | T2: 0.8751 | U2: 0.9254 | V2: 0.9481 | W2: 0.9757 | X2: 1.0188 | Y2: 1.0733 | Z2: 1.2801 | AJ2: 0.9134 | AK2: 0.8764 | AL2: 0.926 | AM2: 0.9473 | AN2: 0.9632 | AO2: 1.0178 | AP2: 1.0656 | AQ2: 1.2791 | BA2: 0.8104 | BB2: 0.7853 | BC2: 0.829 | BD2: 0.842 | BE2: 0.8601 | BF2: 0.8566 | BG2: 0.9149 | BH2: 1.0659 | BR2: 0.8359 | BS2: 0.8083 | BT2: 0.8591 | BU2: 0.872 | BV2: 0.885 | BW2: 0.8802 | BX2: 0.9174 | BY2: 0.9745
A3: 1 | B3: 0.7461 | C3: 0.7187 | D3: 0.7456 | E3: 0.8143 | F3: 0.8162 | G3: 0.8299 | H3: 0.8967 | I3: 1.0159 | S3: 0.8718 | T3: 0.8319 | U3: 0.8945 | V3: 0.9131 | W3: 0.9438 | X3: 0.9847 | Y3: 1.0182 | Z3: 1.2412 | AJ3: 0.8773 | AK3: 0.8341 | AL3: 0.895 | AM3: 0.9122 | AN3: 0.9313 | AO3: 0.9852 | AP3: 1.0116 | AQ3: 1.2397 | BA3: 0.7483 | BB3: 0.7308 | BC3: 0.7741 | BD3: 0.8032 | BE3: 0.8079 | BF3: 0.7682 | BG3: 0.8242 | BH3: 0.9818 | BR3: 0.8043 | BS3: 0.7652 | BT3: 0.8297 | BU3: 0.8494 | BV3: 0.8596 | BW3: 0.8575 | BX3: 0.9024 | BY3: 0.9586
A4: 2 | B4: 0.7387 | C4: 0.7029 | D4: 0.7413 | E4: 0.81 | F4: 0.8094 | G4: 0.8244 | H4: 0.9008 | I4: 1.0173 | S4: 0.8545 | T4: 0.8111 | U4: 0.8673 | V4: 0.896 | W4: 0.9194 | X4: 0.9566 | Y4: 0.9882 | Z4: 1.2173 | AJ4: 0.8588 | AK4: 0.8136 | AL4: 0.8682 | AM4: 0.8944 | AN4: 0.9072 | AO4: 0.9563 | AP4: 0.9806 | AQ4: 1.2157 | BA4: 0.6977 | BB4: 0.6857 | BC4: 0.7247 | BD4: 0.7789 | BE4: 0.7583 | BF4: 0.6892 | BG4: 0.7611 | BH4: 0.9391 | BR4: 0.79 | BS4: 0.7445 | BT4: 0.82 | BU4: 0.8407 | BV4: 0.8484 | BW4: 0.8506 | BX4: 0.8978 | BY4: 0.9519
A5: 3 | B5: 0.7738 | C5: 0.7458 | D5: 0.7799 | E5: 0.8564 | F5: 0.8489 | G5: 0.8705 | H5: 0.9477 | I5: 1.0564 | S5: 0.8604 | T5: 0.8215 | U5: 0.8686 | V5: 0.9061 | W5: 0.9303 | X5: 0.9597 | Y5: 0.996 | Z5: 1.2334 | AJ5: 0.8633 | AK5: 0.8239 | AL5: 0.8697 | AM5: 0.9054 | AN5: 0.9184 | AO5: 0.9574 | AP5: 0.9857 | AQ5: 1.2319 | BA5: 0.7282 | BB5: 0.7026 | BC5: 0.7591 | BD5: 0.8084 | BE5: 0.7923 | BF5: 0.7279 | BG5: 0.7787 | BH5: 0.9885 | BR5: 0.8108 | BS5: 0.7714 | BT5: 0.8378 | BU5: 0.8588 | BV5: 0.8673 | BW5: 0.8697 | BX5: 0.9167 | BY5: 0.9733
A6: 4 | B6: 0.9055 | C6: 0.8905 | D6: 0.913 | E6: 0.9875 | F6: 0.9863 | G6: 1.0208 | H6: 1.0628 | I6: 1.1667 | S6: 0.8944 | T6: 0.8858 | U6: 0.9268 | V6: 0.96 | W6: 1.0045 | X6: 1.0305 | Y6: 1.0744 | Z6: 1.3178 | AJ6: 0.8944 | AK6: 0.8875 | AL6: 0.927 | AM6: 0.9582 | AN6: 0.9916 | AO6: 1.0231 | AP6: 1.0566 | AQ6: 1.3155 | BA6: 0.837 | BB6: 0.8135 | BC6: 0.8807 | BD6: 0.9157 | BE6: 0.9003 | BF6: 0.8623 | BG6: 0.9176 | BH6: 1.1341 | BR6: 0.892 | BS6: 0.8747 | BT6: 0.9157 | BU6: 0.935 | BV6: 0.9405 | BW6: 0.9483 | BX6: 0.997 | BY6: 1.0544
A7: 5 | B7: 1.0721 | C7: 1.0666 | D7: 1.0695 | E7: 1.1114 | F7: 1.1422 | G7: 1.1649 | H7: 1.1869 | I7: 1.2218 | S7: 0.9586 | T7: 0.9629 | U7: 0.9956 | V7: 1.044 | W7: 1.1035 | X7: 1.168 | Y7: 1.2294 | Z7: 1.4006 | AJ7: 0.9565 | AK7: 0.9624 | AL7: 0.9939 | AM7: 1.0422 | AN7: 1.0883 | AO7: 1.1476 | AP7: 1.1996 | AQ7: 1.393 | BA7: 1.0065 | BB7: 0.9742 | BC7: 1.0259 | BD7: 1.0545 | BE7: 1.0702 | BF7: 1.0888 | BG7: 1.1352 | BH7: 1.2658 | BR7: 1.0079 | BS7: 1.0152 | BT7: 1.0194 | BU7: 1.0375 | BV7: 1.0589 | BW7: 1.0694 | BX7: 1.0933 | BY7: 1.1057
A8: 6 | B8: 1.1763 | C8: 1.1929 | D8: 1.1878 | E8: 1.1791 | F8: 1.182 | G8: 1.19 | H8: 1.2039 | I8: 1.1646 | S8: 1.0297 | T8: 1.0354 | U8: 1.0603 | V8: 1.0961 | W8: 1.1621 | X8: 1.2049 | Y8: 1.2756 | Z8: 1.3048 | AJ8: 1.0245 | AK8: 1.031 | AL8: 1.0556 | AM8: 1.0928 | AN8: 1.1462 | AO8: 1.1775 | AP8: 1.2433 | AQ8: 1.277 | BA8: 1.1347 | BB8: 1.1154 | BC8: 1.1486 | BD8: 1.1396 | BE8: 1.1734 | BF8: 1.2625 | BG8: 1.2872 | BH8: 1.2767 | BR8: 1.0928 | BS8: 1.1004 | BT8: 1.1008 | BU8: 1.101 | BV8: 1.1265 | BW8: 1.1316 | BX8: 1.1267 | BY8: 1.0984
A9: 7 | B9: 1.1559 | C9: 1.1741 | D9: 1.1647 | E9: 1.1165 | F9: 1.1216 | G9: 1.0695 | H9: 1.0825 | I9: 0.9737 | S9: 1.0604 | T9: 1.0647 | U9: 1.0697 | V9: 1.0756 | W9: 1.1047 | X9: 1.0979 | Y9: 1.0803 | Z9: 0.9433 | AJ9: 1.0541 | AK9: 1.0586 | AL9: 1.0666 | AM9: 1.0733 | AN9: 1.0906 | AO9: 1.0803 | AP9: 1.0752 | AQ9: 0.9225 | BA9: 1.157 | BB9: 1.1506 | BC9: 1.1565 | BD9: 1.1131 | BE9: 1.1501 | BF9: 1.194 | BG9: 1.2031 | BH9: 1.054 | BR9: 1.1114 | BS9: 1.1178 | BT9: 1.11 | BU9: 1.079 | BV9: 1.1136 | BW9: 1.1055 | BX9: 1.084 | BY9: 1.0313
A10: 8 | B10: 1.092 | C10: 1.087 | D10: 1.0992 | E10: 1.0175 | F10: 0.9948 | G10: 0.9075 | H10: 0.871 | I10: 0.7613 | S10: 1.0666 | T10: 1.0562 | U10: 1.0427 | V10: 1.0114 | W10: 0.9602 | X10: 0.8981 | Y10: 0.7847 | Z10: 0.5653 | AJ10: 1.0613 | AK10: 1.0542 | AL10: 1.0416 | AM10: 1.0145 | AN10: 0.9592 | AO10: 0.8987 | AP10: 0.8079 | AQ10: 0.5812 | BA10: 1.1247 | BB10: 1.1187 | BC10: 1.1127 | BD10: 1.0563 | BE10: 1.052 | BF10: 1.0219 | BG10: 0.9498 | BH10: 0.7767 | BR10: 1.0666 | BS10: 1.0589 | BT10: 1.07 | BU10: 1.0198 | BV10: 1.0305 | BW10: 1.011 | BX10: 0.9847 | BY10: 0.9311
A11: 9 | B11: 1.0408 | C11: 1.0181 | D11: 1.0419 | E11: 0.9349 | F11: 0.894 | G11: 0.7729 | H11: 0.7065 | I11: 0.5806 | S11: 1.0601 | T11: 1.0421 | U11: 1.0062 | V11: 0.9489 | W11: 0.846 | X11: 0.7428 | Y11: 0.5911 | Z11: 0.355 | AJ11: 1.0563 | AK11: 1.0414 | AL11: 1.0066 | AM11: 0.9554 | AN11: 0.8738 | AO11: 0.7594 | AP11: 0.6216 | AQ11: 0.4072 | BA11: 1.0959 | BB11: 1.0892 | BC11: 1.0645 | BD11: 1.0268 | BE11: 0.9623 | BF11: 0.8568 | BG11: 0.75 | BH11: 0.5594 | BR11: 1.0106 | BS11: 1.0036 | BT11: 1.0281 | BU11: 0.9813 | BV11: 0.9468 | BW11: 0.9284 | BX11: 0.8928 | BY11: 0.8345
A12: 10 | B12: 0.9913 | C12: 0.9603 | D12: 0.9974 | E12: 0.8741 | F12: 0.8147 | G12: 0.6775 | H12: 0.5853 | I12: 0.439 | S12: 1.0513 | T12: 1.0356 | U12: 0.9774 | V12: 0.9186 | W12: 0.7939 | X12: 0.6619 | Y12: 0.4989 | Z12: 0.2772 | AJ12: 1.0493 | AK12: 1.036 | AL12: 0.9779 | AM12: 0.9218 | AN12: 0.8245 | AO12: 0.6847 | AP12: 0.5296 | AQ12: 0.3327 | BA12: 1.0631 | BB12: 1.0765 | BC12: 1.0397 | BD12: 1.0117 | BE12: 0.9039 | BF12: 0.7729 | BG12: 0.662 | BH12: 0.4391 | BR12: 0.9436 | BS12: 0.9628 | BT12: 0.9903 | BU12: 0.9478 | BV12: 0.8816 | BW12: 0.8501 | BX12: 0.813 | BY12: 0.7512
A13: 11 | B13: 0.9352 | C13: 0.8779 | D13: 0.9344 | E13: 0.8171 | F13: 0.7407 | G13: 0.6043 | H13: 0.5145 | I13: 0.3466 | S13: 1.0429 | T13: 1.0237 | U13: 0.9592 | V13: 0.9013 | W13: 0.7607 | X13: 0.6263 | Y13: 0.4519 | Z13: 0.2446 | AJ13: 1.0416 | AK13: 1.0243 | AL13: 0.9595 | AM13: 0.9046 | AN13: 0.7942 | AO13: 0.6445 | AP13: 0.4846 | AQ13: 0.2874 | BA13: 1.0124 | BB13: 1.0217 | BC13: 0.9822 | BD13: 0.9605 | BE13: 0.8216 | BF13: 0.6904 | BG13: 0.5817 | BH13: 0.3284 | BR13: 0.902 | BS13: 0.9131 | BT13: 0.9563 | BU13: 0.9086 | BV13: 0.836 | BW13: 0.8089 | BX13: 0.774 | BY13: 0.7175
... A25: 23 | B25: 0.813 | C25: 0.8075 | D25: 0.8111 | E25: 0.8721 | F25: 0.8831 | G25: 0.8994 | H25: 0.9592 | I25: 1.0744 | S25: 0.9624 | T25: 0.94 | U25: 0.9829 | V25: 1.0053 | W25: 1.0393 | X25: 1.0911 | Y25: 1.1575 | Z25: 1.3435 | AJ25: 0.9671 | AK25: 0.9414 | AL25: 0.9837 | AM25: 1.0047 | AN25: 1.0263 | AO25: 1.0869 | AP25: 1.1509 | AQ25: 1.3418 | BA25: 0.8771 | BB25: 0.8444 | BC25: 0.8754 | BD25: 0.8729 | BE25: 0.9083 | BF25: 0.9339 | BG25: 0.9906 | BH25: 1.1588 | BR25: 0.889 | BS25: 0.8659 | BT25: 0.8998 | BU25: 0.9074 | BV25: 0.9209 | BW25: 0.9179 | BX25: 0.9508 | BY25: 1.0089

Sheet Fig3_NegHours
A1: year | B1: Germany_neg | C1: Spain_neg | D1: Portugal_neg | E1: France_neg | F1: Italy_neg | G1: Germany_nearneg | H1: Spain_nearneg | I1: Portugal_nearneg | J1: France_nearneg | K1: Italy_nearneg
A2: 2019 | B2: 211 | C2: 0 | D2: 0 | E2: 27 | F2: 0 | G2: 272 | H2: 10 | I2: 17 | J2: 38 | K2: 0
A3: 2020 | B3: 298 | C3: 0 | D3: 0 | E3: 102 | F3: 0 | G3: 435 | H3: 0 | I3: 0 | J3: 151 | K3: 11
A4: 2021 | B4: 139 | C4: 0 | D4: 0 | E4: 64 | F4: 0 | G4: 204 | H4: 40 | I4: 44 | J4: 114 | K4: 0
A5: 2022 | B5: 70 | C5: 0 | D5: 0 | E5: 4 | F5: 0 | G5: 125 | H5: 19 | I5: 23 | J5: 26 | K5: 0
A6: 2023 | B6: 300 | C6: 0 | D6: 0 | E6: 147 | F6: 0 | G6: 425 | H6: 171 | I6: 122 | J6: 271 | K6: 0
A7: 2024 | B7: 457 | C7: 247 | D7: 196 | E7: 352 | F7: 0 | G7: 628 | H7: 1064 | I7: 1012 | J7: 739 | K7: 4
A8: 2025 | B8: 576 | C8: 556 | D8: 200 | E8: 513 | F8: 0 | G8: 749 | H8: 1048 | I8: 646 | J8: 853 | K8: 13
A9: 2026 | B9: 471 | C9: 747 | D9: 599 | E9: 563 | F9: 0 | G9: 547 | H9: 1280 | I9: 1204 | J9: 830 | K9: 24
A10: 2027
A11: 2028
A12: 2029
A13: 2030
A14: 2031
A15: 2032
A16: 2033
A17: 2034
A18: 2035

Sheet Fig3_CumNeg
A1: doy | B1: DE_2019 | C1: DE_2020 | D1: DE_2021 | E1: DE_2022 | F1: DE_2023 | G1: DE_2024 | H1: DE_2025 | I1: DE_2026 | J1: DE_2027 | K1: DE_2028 | L1: DE_2029 | M1: DE_2030 | N1: DE_2031 | O1: DE_2032 | P1: DE_2033 | Q1: DE_2034 | R1: DE_2035 | S1: ES_2019 | T1: ES_2020 | U1: ES_2021 | V1: ES_2022 | W1: ES_2023 | X1: ES_2024 | Y1: ES_2025 | Z1: ES_2026 | AA1: ES_2027 | AB1: ES_2028 | AC1: ES_2029 | AD1: ES_2030 | AE1: ES_2031 | AF1: ES_2032 | AG1: ES_2033 | AH1: ES_2034 | AI1: ES_2035 | AJ1: PT_2019 | AK1: PT_2020 | AL1: PT_2021 | AM1: PT_2022 | AN1: PT_2023 | AO1: PT_2024 | AP1: PT_2025 | AQ1: PT_2026 | AR1: PT_2027 | AS1: PT_2028 | AT1: PT_2029 | AU1: PT_2030 | AV1: PT_2031 | AW1: PT_2032 | AX1: PT_2033 | AY1: PT_2034 | AZ1: PT_2035 | BA1: FR_2019 | BB1: FR_2020 | BC1: FR_2021 | BD1: FR_2022 | BE1: FR_2023 | BF1: FR_2024 | BG1: FR_2025 | BH1: FR_2026 | BI1: FR_2027 | BJ1: FR_2028 | BK1: FR_2029 | BL1: FR_2030 | BM1: FR_2031 | BN1: FR_2032 | BO1: FR_2033 | BP1: FR_2034 | BQ1: FR_2035 | BR1: IT_2019 | BS1: IT_2020 | BT1: IT_2021 | BU1: IT_2022 | BV1: IT_2023 | BW1: IT_2024 | BX1: IT_2025 | BY1: IT_2026 | BZ1: IT_2027 | CA1: IT_2028 | CB1: IT_2029 | CC1: IT_2030 | CD1: IT_2031 | CE1: IT_2032 | CF1: IT_2033 | CG1: IT_2034 | CH1: IT_2035
A2: 1 | B2: 21 | C2: 0 | D2: 0 | E2: 0 | F2: 14 | G2: 11 | H2: 17 | I2: 11 | S2: 0 | T2: 0 | U2: 0 | V2: 0 | W2: 15 | X2: 0 | Y2: 0 | Z2: 0 | AJ2: 0 | AK2: 0 | AL2: 0 | AM2: 0 | AN2: 15 | AO2: 0 | AP2: 0 | AQ2: 0 | BA2: 0 | BB2: 0 | BC2: 0 | BD2: 0 | BE2: 13 | BF2: 11 | BG2: 0 | BH2: 0 | BR2: 0 | BS2: 0 | BT2: 0 | BU2: 0 | BV2: 0 | BW2: 0 | BX2: 0 | BY2: 0
A3: 2 | B3: 27 | C3: 0 | D3: 0 | E3: 1 | F3: 14 | G3: 12 | H3: 17 | I3: 12 | S3: 0 | T3: 0 | U3: 0 | V3: 0 | W3: 15 | X3: 0 | Y3: 0 | Z3: 0 | AJ3: 0 | AK3: 0 | AL3: 0 | AM3: 0 | AN3: 15 | AO3: 0 | AP3: 0 | AQ3: 0 | BA3: 0 | BB3: 0 | BC3: 0 | BD3: 0 | BE3: 13 | BF3: 15 | BG3: 0 | BH3: 0 | BR3: 0 | BS3: 0 | BT3: 0 | BU3: 0 | BV3: 0 | BW3: 0 | BX3: 0 | BY3: 0
A4: 3 | B4: 27 | C4: 2 | D4: 0 | E4: 6 | F4: 14 | G4: 17 | H4: 17 | I4: 12 | S4: 0 | T4: 0 | U4: 0 | V4: 0 | W4: 15 | X4: 0 | Y4: 0 | Z4: 0 | AJ4: 0 | AK4: 0 | AL4: 0 | AM4: 0 | AN4: 15 | AO4: 0 | AP4: 0 | AQ4: 0 | BA4: 0 | BB4: 0 | BC4: 0 | BD4: 2 | BE4: 13 | BF4: 20 | BG4: 0 | BH4: 0 | BR4: 0 | BS4: 0 | BT4: 0 | BU4: 0 | BV4: 0 | BW4: 0 | BX4: 0 | BY4: 0
A5: 4 | B5: 27 | C5: 4 | D5: 0 | E5: 6 | F5: 16 | G5: 17 | H5: 17 | I5: 12 | S5: 0 | T5: 0 | U5: 0 | V5: 0 | W5: 15 | X5: 0 | Y5: 0 | Z5: 0 | AJ5: 0 | AK5: 0 | AL5: 0 | AM5: 0 | AN5: 15 | AO5: 0 | AP5: 0 | AQ5: 0 | BA5: 0 | BB5: 0 | BC5: 0 | BD5: 2 | BE5: 13 | BF5: 20 | BG5: 0 | BH5: 0 | BR5: 0 | BS5: 0 | BT5: 0 | BU5: 0 | BV5: 0 | BW5: 0 | BX5: 0 | BY5: 0
A6: 5 | B6: 27 | C6: 4 | D6: 0 | E6: 6 | F6: 19 | G6: 17 | H6: 17 | I6: 12 | S6: 0 | T6: 0 | U6: 0 | V6: 0 | W6: 15 | X6: 0 | Y6: 0 | Z6: 0 | AJ6: 0 | AK6: 0 | AL6: 0 | AM6: 0 | AN6: 15 | AO6: 0 | AP6: 0 | AQ6: 0 | BA6: 0 | BB6: 0 | BC6: 0 | BD6: 2 | BE6: 13 | BF6: 20 | BG6: 0 | BH6: 0 | BR6: 0 | BS6: 0 | BT6: 0 | BU6: 0 | BV6: 0 | BW6: 0 | BX6: 0 | BY6: 0
A7: 6 | B7: 27 | C7: 4 | D7: 0 | E7: 6 | F7: 19 | G7: 17 | H7: 17 | I7: 12 | S7: 0 | T7: 0 | U7: 0 | V7: 0 | W7: 15 | X7: 0 | Y7: 0 | Z7: 4 | AJ7: 0 | AK7: 0 | AL7: 0 | AM7: 0 | AN7: 15 | AO7: 0 | AP7: 0 | AQ7: 0 | BA7: 0 | BB7: 0 | BC7: 0 | BD7: 2 | BE7: 13 | BF7: 20 | BG7: 0 | BH7: 0 | BR7: 0 | BS7: 0 | BT7: 0 | BU7: 0 | BV7: 0 | BW7: 0 | BX7: 0 | BY7: 0
A8: 7 | B8: 27 | C8: 4 | D8: 0 | E8: 6 | F8: 19 | G8: 17 | H8: 17 | I8: 12 | S8: 0 | T8: 0 | U8: 0 | V8: 0 | W8: 15 | X8: 0 | Y8: 0 | Z8: 4 | AJ8: 0 | AK8: 0 | AL8: 0 | AM8: 0 | AN8: 15 | AO8: 0 | AP8: 0 | AQ8: 0 | BA8: 0 | BB8: 0 | BC8: 0 | BD8: 2 | BE8: 13 | BF8: 20 | BG8: 1 | BH8: 0 | BR8: 0 | BS8: 0 | BT8: 0 | BU8: 0 | BV8: 0 | BW8: 0 | BX8: 0 | BY8: 0
A9: 8 | B9: 27 | C9: 6 | D9: 0 | E9: 6 | F9: 19 | G9: 17 | H9: 17 | I9: 12 | S9: 0 | T9: 0 | U9: 0 | V9: 0 | W9: 15 | X9: 0 | Y9: 0 | Z9: 4 | AJ9: 0 | AK9: 0 | AL9: 0 | AM9: 0 | AN9: 15 | AO9: 0 | AP9: 0 | AQ9: 0 | BA9: 0 | BB9: 0 | BC9: 0 | BD9: 2 | BE9: 13 | BF9: 20 | BG9: 1 | BH9: 0 | BR9: 0 | BS9: 0 | BT9: 0 | BU9: 0 | BV9: 0 | BW9: 0 | BX9: 0 | BY9: 0
A10: 9 | B10: 27 | C10: 6 | D10: 0 | E10: 6 | F10: 19 | G10: 17 | H10: 17 | I10: 12 | S10: 0 | T10: 0 | U10: 0 | V10: 0 | W10: 15 | X10: 0 | Y10: 0 | Z10: 4 | AJ10: 0 | AK10: 0 | AL10: 0 | AM10: 0 | AN10: 15 | AO10: 0 | AP10: 0 | AQ10: 0 | BA10: 0 | BB10: 0 | BC10: 0 | BD10: 2 | BE10: 13 | BF10: 20 | BG10: 1 | BH10: 0 | BR10: 0 | BS10: 0 | BT10: 0 | BU10: 0 | BV10: 0 | BW10: 0 | BX10: 0 | BY10: 0
A11: 10 | B11: 27 | C11: 6 | D11: 0 | E11: 6 | F11: 19 | G11: 17 | H11: 17 | I11: 12 | S11: 0 | T11: 0 | U11: 0 | V11: 0 | W11: 15 | X11: 0 | Y11: 0 | Z11: 4 | AJ11: 0 | AK11: 0 | AL11: 0 | AM11: 0 | AN11: 15 | AO11: 0 | AP11: 0 | AQ11: 0 | BA11: 0 | BB11: 0 | BC11: 0 | BD11: 2 | BE11: 13 | BF11: 20 | BG11: 1 | BH11: 0 | BR11: 0 | BS11: 0 | BT11: 0 | BU11: 0 | BV11: 0 | BW11: 0 | BX11: 0 | BY11: 0
A12: 11 | B12: 27 | C12: 6 | D12: 0 | E12: 6 | F12: 23 | G12: 17 | H12: 17 | I12: 12 | S12: 0 | T12: 0 | U12: 0 | V12: 0 | W12: 15 | X12: 0 | Y12: 0 | Z12: 4 | AJ12: 0 | AK12: 0 | AL12: 0 | AM12: 0 | AN12: 15 | AO12: 0 | AP12: 0 | AQ12: 0 | BA12: 0 | BB12: 0 | BC12: 0 | BD12: 2 | BE12: 16 | BF12: 20 | BG12: 1 | BH12: 0 | BR12: 0 | BS12: 0 | BT12: 0 | BU12: 0 | BV12: 0 | BW12: 0 | BX12: 0 | BY12: 0
A13: 12 | B13: 27 | C13: 6 | D13: 0 | E13: 6 | F13: 24 | G13: 17 | H13: 17 | I13: 12 | S13: 0 | T13: 0 | U13: 0 | V13: 0 | W13: 15 | X13: 0 | Y13: 0 | Z13: 4 | AJ13: 0 | AK13: 0 | AL13: 0 | AM13: 0 | AN13: 15 | AO13: 0 | AP13: 0 | AQ13: 0 | BA13: 0 | BB13: 0 | BC13: 0 | BD13: 2 | BE13: 16 | BF13: 20 | BG13: 1 | BH13: 0 | BR13: 0 | BS13: 0 | BT13: 0 | BU13: 0 | BV13: 0 | BW13: 0 | BX13: 0 | BY13: 0
... A284: 283 | B284: 212 | C284: 367 | D284: 190 | E284: 80 | F284: 278 | G284: 570 | H284: 725 | I284: 547 | S284: 0 | T284: 0 | U284: 40 | V284: 0 | W284: 115 | X284: 1048 | Y284: 983 | Z284: 1280 | AJ284: 0 | AK284: 0 | AL284: 44 | AM284: 0 | AN284: 66 | AO284: 998 | AP284: 599 | AQ284: 1204 | BA284: 36 | BB284: 123 | BC284: 110 | BD284: 4 | BE284: 176 | BF284: 714 | BG284: 840 | BH284: 830 | BR284: 0 | BS284: 11 | BT284: 0 | BU284: 0 | BV284: 0 | BW284: 4 | BX284: 13 | BY284: 24
A285: 284 | B285: 214 | C285: 367 | D285: 190 | E285: 80 | F285: 282 | G285: 570 | H285: 725 | S285: 0 | T285: 0 | U285: 40 | V285: 0 | W285: 115 | X285: 1048 | Y285: 983 | AJ285: 0 | AK285: 0 | AL285: 44 | AM285: 0 | AN285: 66 | AO285: 998 | AP285: 599 | BA285: 36 | BB285: 123 | BC285: 110 | BD285: 4 | BE285: 176 | BF285: 718 | BG285: 840 | BR285: 0 | BS285: 11 | BT285: 0 | BU285: 0 | BV285: 0 | BW285: 4 | BX285: 13
A286: 285 | B286: 216 | C286: 367 | D286: 190 | E286: 80 | F286: 282 | G286: 570 | H286: 725 | S286: 0 | T286: 0 | U286: 40 | V286: 0 | W286: 115 | X286: 1048 | Y286: 984 | AJ286: 0 | AK286: 0 | AL286: 44 | AM286: 0 | AN286: 66 | AO286: 998 | AP286: 600 | BA286: 36 | BB286: 123 | BC286: 110 | BD286: 4 | BE286: 176 | BF286: 718 | BG286: 840 | BR286: 0 | BS286: 11 | BT286: 0 | BU286: 0 | BV286: 0 | BW286: 4 | BX286: 13
A287: 286 | B287: 217 | C287: 367 | D287: 190 | E287: 80 | F287: 286 | G287: 572 | H287: 725 | S287: 0 | T287: 0 | U287: 40 | V287: 0 | W287: 115 | X287: 1048 | Y287: 984 | AJ287: 0 | AK287: 0 | AL287: 44 | AM287: 0 | AN287: 66 | AO287: 998 | AP287: 600 | BA287: 36 | BB287: 123 | BC287: 110 | BD287: 4 | BE287: 177 | BF287: 720 | BG287: 840 | BR287: 0 | BS287: 11 | BT287: 0 | BU287: 0 | BV287: 0 | BW287: 4 | BX287: 13
A288: 287 | B288: 217 | C288: 367 | D288: 190 | E288: 80 | F288: 298 | G288: 588 | H288: 725 | S288: 0 | T288: 0 | U288: 40 | V288: 0 | W288: 115 | X288: 1051 | Y288: 984 | AJ288: 0 | AK288: 0 | AL288: 44 | AM288: 0 | AN288: 66 | AO288: 1001 | AP288: 600 | BA288: 36 | BB288: 123 | BC288: 110 | BD288: 4 | BE288: 181 | BF288: 729 | BG288: 840 | BR288: 0 | BS288: 11 | BT288: 0 | BU288: 0 | BV288: 0 | BW288: 4 | BX288: 13
A289: 288 | B289: 217 | C289: 367 | D289: 190 | E289: 80 | F289: 303 | G289: 588 | H289: 725 | S289: 0 | T289: 0 | U289: 40 | V289: 0 | W289: 115 | X289: 1051 | Y289: 984 | AJ289: 0 | AK289: 0 | AL289: 44 | AM289: 0 | AN289: 66 | AO289: 1001 | AP289: 600 | BA289: 36 | BB289: 123 | BC289: 110 | BD289: 4 | BE289: 181 | BF289: 729 | BG289: 840 | BR289: 0 | BS289: 11 | BT289: 0 | BU289: 0 | BV289: 0 | BW289: 4 | BX289: 13
A290: 289 | B290: 217 | C290: 367 | D290: 190 | E290: 80 | F290: 303 | G290: 588 | H290: 725 | S290: 0 | T290: 0 | U290: 40 | V290: 0 | W290: 115 | X290: 1051 | Y290: 984 | AJ290: 0 | AK290: 0 | AL290: 44 | AM290: 0 | AN290: 66 | AO290: 1001 | AP290: 600 | BA290: 36 | BB290: 123 | BC290: 110 | BD290: 4 | BE290: 181 | BF290: 729 | BG290: 840 | BR290: 0 | BS290: 11 | BT290: 0 | BU290: 0 | BV290: 0 | BW290: 4 | BX290: 13
A291: 290 | B291: 217 | C291: 367 | D291: 190 | E291: 80 | F291: 303 | G291: 588 | H291: 725 | S291: 0 | T291: 0 | U291: 40 | V291: 0 | W291: 115 | X291: 1051 | Y291: 984 | AJ291: 0 | AK291: 0 | AL291: 44 | AM291: 0 | AN291: 66 | AO291: 1001 | AP291: 600 | BA291: 36 | BB291: 123 | BC291: 110 | BD291: 4 | BE291: 181 | BF291: 729 | BG291: 840 | BR291: 0 | BS291: 11 | BT291: 0 | BU291: 0 | BV291: 0 | BW291: 4 | BX291: 13
A292: 291 | B292: 217 | C292: 367 | D292: 190 | E292: 80 | F292: 303 | G292: 588 | H292: 725 | S292: 0 | T292: 0 | U292: 40 | V292: 0 | W292: 115 | X292: 1053 | Y292: 985 | AJ292: 0 | AK292: 0 | AL292: 44 | AM292: 0 | AN292: 66 | AO292: 1003 | AP292: 600 | BA292: 36 | BB292: 123 | BC292: 110 | BD292: 4 | BE292: 182 | BF292: 729 | BG292: 840 | BR292: 0 | BS292: 11 | BT292: 0 | BU292: 0 | BV292: 0 | BW292: 4 | BX292: 13
A293: 292 | B293: 217 | C293: 367 | D293: 190 | E293: 80 | F293: 303 | G293: 588 | H293: 725 | S293: 0 | T293: 0 | U293: 40 | V293: 0 | W293: 115 | X293: 1053 | Y293: 990 | AJ293: 0 | AK293: 0 | AL293: 44 | AM293: 0 | AN293: 66 | AO293: 1003 | AP293: 605 | BA293: 36 | BB293: 123 | BC293: 110 | BD293: 4 | BE293: 182 | BF293: 729 | BG293: 840 | BR293: 0 | BS293: 11 | BT293: 0 | BU293: 0 | BV293: 0 | BW293: 4 | BX293: 13
A294: 293 | B294: 217 | C294: 367 | D294: 192 | E294: 80 | F294: 303 | G294: 588 | H294: 725 | S294: 0 | T294: 0 | U294: 40 | V294: 0 | W294: 115 | X294: 1053 | Y294: 992 | AJ294: 0 | AK294: 0 | AL294: 44 | AM294: 0 | AN294: 66 | AO294: 1003 | AP294: 606 | BA294: 36 | BB294: 123 | BC294: 111 | BD294: 4 | BE294: 182 | BF294: 729 | BG294: 841 | BR294: 0 | BS294: 11 | BT294: 0 | BU294: 0 | BV294: 0 | BW294: 4 | BX294: 13
A295: 294 | B295: 217 | C295: 367 | D295: 192 | E295: 80 | F295: 303 | G295: 595 | H295: 725 | S295: 0 | T295: 0 | U295: 40 | V295: 0 | W295: 115 | X295: 1059 | Y295: 992 | AJ295: 0 | AK295: 0 | AL295: 44 | AM295: 0 | AN295: 66 | AO295: 1007 | AP295: 606 | BA295: 36 | BB295: 123 | BC295: 114 | BD295: 4 | BE295: 182 | BF295: 736 | BG295: 841 | BR295: 0 | BS295: 11 | BT295: 0 | BU295: 0 | BV295: 0 | BW295: 4 | BX295: 13
A296: 295 | B296: 217 | C296: 367 | D296: 192 | E296: 80 | F296: 303 | G296: 598 | H296: 725 | S296: 0 | T296: 0 | U296: 40 | V296: 0 | W296: 115 | X296: 1059 | Y296: 996 | AJ296: 0 | AK296: 0 | AL296: 44 | AM296: 0 | AN296: 66 | AO296: 1007 | AP296: 610 | BA296: 36 | BB296: 123 | BC296: 114 | BD296: 4 | BE296: 182 | BF296: 739 | BG296: 841 | BR296: 0 | BS296: 11 | BT296: 0 | BU296: 0 | BV296: 0 | BW296: 4 | BX296: 13
... A366: 365 | B366: 272 | C366: 435 | D366: 204 | E366: 125 | F366: 425 | G366: 627 | H366: 749 | S366: 10 | T366: 0 | U366: 40 | V366: 19 | W366: 171 | X366: 1064 | Y366: 1048 | AJ366: 17 | AK366: 0 | AL366: 44 | AM366: 23 | AN366: 122 | AO366: 1012 | AP366: 646 | BA366: 38 | BB366: 151 | BC366: 114 | BD366: 26 | BE366: 271 | BF366: 739 | BG366: 853 | BR366: 0 | BS366: 11 | BT366: 0 | BU366: 0 | BV366: 0 | BW366: 4 | BX366: 13
A367: 366 | C367: 435 | G367: 628 | T367: 0 | X367: 1064 | AK367: 0 | AO367: 1012 | BB367: 151 | BF367: 739 | BS367: 11 | BW367: 4

Sheet Fig4_Duration
A1: pct_of_hours | B1: DE_2019 | C1: DE_2020 | D1: DE_2021 | E1: DE_2022 | F1: DE_2023 | G1: DE_2024 | H1: DE_2025 | I1: DE_2026 | J1: DE_2027 | K1: DE_2028 | L1: DE_2029 | M1: DE_2030 | N1: DE_2031 | O1: DE_2032 | P1: DE_2033 | Q1: DE_2034 | R1: DE_2035 | S1: ES_2019 | T1: ES_2020 | U1: ES_2021 | V1: ES_2022 | W1: ES_2023 | X1: ES_2024 | Y1: ES_2025 | Z1: ES_2026 | AA1: ES_2027 | AB1: ES_2028 | AC1: ES_2029 | AD1: ES_2030 | AE1: ES_2031 | AF1: ES_2032 | AG1: ES_2033 | AH1: ES_2034 | AI1: ES_2035 | AJ1: PT_2019 | AK1: PT_2020 | AL1: PT_2021 | AM1: PT_2022 | AN1: PT_2023 | AO1: PT_2024 | AP1: PT_2025 | AQ1: PT_2026 | AR1: PT_2027 | AS1: PT_2028 | AT1: PT_2029 | AU1: PT_2030 | AV1: PT_2031 | AW1: PT_2032 | AX1: PT_2033 | AY1: PT_2034 | AZ1: PT_2035 | BA1: FR_2019 | BB1: FR_2020 | BC1: FR_2021 | BD1: FR_2022 | BE1: FR_2023 | BF1: FR_2024 | BG1: FR_2025 | BH1: FR_2026 | BI1: FR_2027 | BJ1: FR_2028 | BK1: FR_2029 | BL1: FR_2030 | BM1: FR_2031 | BN1: FR_2032 | BO1: FR_2033 | BP1: FR_2034 | BQ1: FR_2035 | BR1: IT_2019 | BS1: IT_2020 | BT1: IT_2021 | BU1: IT_2022 | BV1: IT_2023 | BW1: IT_2024 | BX1: IT_2025 | BY1: IT_2026 | BZ1: IT_2027 | CA1: IT_2028 | CB1: IT_2029 | CC1: IT_2030 | CD1: IT_2031 | CE1: IT_2032 | CF1: IT_2033 | CG1: IT_2034 | CH1: IT_2035
A2: 0 | B2: 121.46 | C2: 200.04 | D2: 620 | E2: 871 | F2: 524.27 | G2: 936.28 | H2: 583.4 | I2: 697.31 | S2: 74.74 | T2: 68.9 | U2: 409 | V2: 700 | W2: 220 | X2: 193 | Y2: 240 | Z2: 296.25 | AJ2: 74.74 | AK2: 68.9 | AL2: 409 | AM2: 651 | AN2: 220 | AO2: 193 | AP2: 240 | AQ2: 336.51 | BA2: 121.46 | BB2: 200.04 | BC2: 620 | BD2: 2987.78 | BE2: 276.12 | BF2: 284.21 | BG2: 473.28 | BH2: 353.74 | BR2: 108.49 | BS2: 162.6 | BT2: 533.19 | BU2: 870 | BV2: 295 | BW2: 275.08 | BX2: 289 | BY2: 347.63
A3: 1 | B3: 72.52 | C3: 74.84 | D3: 366.82 | E3: 664.94 | F3: 207.98 | G3: 224.86 | H3: 242.84 | I3: 265.27 | S3: 69.74 | T3: 57.17 | U3: 334.55 | V3: 397.47 | W3: 165.74 | X3: 158.27 | Y3: 169.56 | Z3: 234.05 | AJ3: 69.81 | AK3: 56.62 | AL3: 334.55 | AM3: 395.65 | AN3: 165.22 | AO3: 158.47 | AP3: 169.22 | AQ3: 234.08 | BA3: 75.91 | BB3: 75.38 | BC3: 399.28 | BD3: 703.63 | BE3: 209.5 | BF3: 152 | BG3: 175.82 | BH3: 240.86 | BR3: 82.92 | BS3: 77.94 | BT3: 381.17 | BU3: 702.94 | BV3: 225.35 | BW3: 192.46 | BX3: 185.84 | BY3: 266.06
A4: 2 | B4: 66.75 | C4: 64.21 | D4: 322.2 | E4: 590.7 | F4: 190 | G4: 181.39 | H4: 197.14 | I4: 239.89 | S4: 68.38 | T4: 54.89 | U4: 307.92 | V4: 330.07 | W4: 160 | X4: 150 | Y4: 158.37 | Z4: 220.02 | AJ4: 68.4 | AK4: 54.56 | AL4: 307.92 | AM4: 330.07 | AN4: 159.37 | AO4: 150 | AP4: 157.84 | AQ4: 219.52 | BA4: 70.86 | BB4: 65.78 | BC4: 351.57 | BD4: 650 | BE4: 193.02 | BF4: 137.82 | BG4: 160.16 | BH4: 222.3 | BR4: 79.89 | BS4: 72.34 | BT4: 339.58 | BU4: 650 | BV4: 213.43 | BW4: 178.88 | BX4: 175.68 | BY4: 254.99
A5: 3 | B5: 62.45 | C5: 59.67 | D5: 291.81 | E5: 559.89 | F5: 179.97 | G5: 160.95 | H5: 179.92 | I5: 224.38 | S5: 67.21 | T5: 53.54 | U5: 285.23 | V5: 291.01 | W5: 154.07 | X5: 144.36 | Y5: 151.25 | Z5: 209.83 | AJ5: 67.66 | AK5: 53.28 | AL5: 285.23 | AM5: 291.01 | AN5: 153.93 | AO5: 144.38 | AP5: 150.99 | AQ5: 209.64 | BA5: 68.51 | BB5: 61.89 | BC5: 326.92 | BD5: 610.13 | BE5: 182.24 | BF5: 131 | BG5: 150.96 | BH5: 209.3 | BR5: 77.34 | BS5: 69.12 | BT5: 319.27 | BU5: 619.35 | BV5: 204.02 | BW5: 171.18 | BX5: 170 | BY5: 245.01
A6: 4 | B6: 60 | C6: 56.96 | D6: 269.02 | E6: 530 | F6: 171.63 | G6: 151.06 | H6: 170 | I6: 210.25 | S6: 66.03 | T6: 52.85 | U6: 265.35 | V6: 278.33 | W6: 150.45 | X6: 140.09 | Y6: 145.02 | Z6: 202.96 | AJ6: 66.5 | AK6: 52.53 | AL6: 265.35 | AM6: 278 | AN6: 150 | AO6: 140.09 | AP6: 145 | AQ6: 202.84 | BA6: 66.68 | BB6: 59.17 | BC6: 305.81 | BD6: 577.37 | BE6: 175.66 | BF6: 126.43 | BG6: 143.63 | BH6: 200.01 | BR6: 75.42 | BS6: 66.22 | BT6: 304.34 | BU6: 592.9 | BV6: 198.22 | BW6: 166.51 | BX6: 165.06 | BY6: 238.75
A7: 5 | B7: 58.29 | C7: 55.16 | D7: 248.85 | E7: 509.98 | F7: 166.25 | G7: 143.25 | H7: 162.35 | I7: 202.97 | S7: 64.21 | T7: 51.89 | U7: 254.46 | V7: 268.18 | W7: 146.96 | X7: 136.59 | Y7: 139.01 | Z7: 198.34 | AJ7: 65 | AK7: 51.73 | AL7: 254.76 | AM7: 268.04 | AN7: 146.73 | AO7: 136.59 | AP7: 138.86 | AQ7: 197.99 | BA7: 64.63 | BB7: 56.9 | BC7: 287.75 | BD7: 553.3 | BE7: 170.07 | BF7: 122.83 | BG7: 138.02 | BH7: 193.52 | BR7: 74.28 | BS7: 64.44 | BT7: 290.51 | BU7: 571.36 | BV7: 193.67 | BW7: 162.08 | BX7: 161.32 | BY7: 230.84
A8: 6 | B8: 56.82 | C8: 53.89 | D8: 233.68 | E8: 493.9 | F8: 161.79 | G8: 137.84 | H8: 155.78 | I8: 197.03 | S8: 63.06 | T8: 51.02 | U8: 248.02 | V8: 261.39 | W8: 144.22 | X8: 133.06 | Y8: 134.76 | Z8: 193.84 | AJ8: 63.64 | AK8: 50.92 | AL8: 248.02 | AM8: 260.79 | AN8: 143.9 | AO8: 133.02 | AP8: 134.42 | AQ8: 193.58 | BA8: 62.63 | BB8: 55.22 | BC8: 272.26 | BD8: 534.02 | BE8: 165.38 | BF8: 119.55 | BG8: 133.7 | BH8: 186.58 | BR8: 73.41 | BS8: 62.68 | BT8: 277.88 | BU8: 551.8 | BV8: 189.98 | BW8: 158.42 | BX8: 158.8 | BY8: 224.77
A9: 7 | B9: 55.59 | C9: 52.53 | D9: 221.06 | E9: 478.13 | F9: 157.07 | G9: 134.4 | H9: 151 | I9: 191.73 | S9: 61.57 | T9: 50.5 | U9: 240.52 | V9: 255 | W9: 141.54 | X9: 130 | Y9: 131.11 | Z9: 189.92 | AJ9: 62.01 | AK9: 50.27 | AL9: 240.45 | AM9: 255 | AN9: 141.39 | AO9: 130 | AP9: 130.86 | AQ9: 189.72 | BA9: 60.49 | BB9: 54 | BC9: 258.45 | BD9: 516.44 | BE9: 161.21 | BF9: 116.74 | BG9: 129.78 | BH9: 182.07 | BR9: 72.49 | BS9: 61.14 | BT9: 267.21 | BU9: 534.98 | BV9: 186.21 | BW9: 154.7 | BX9: 155.85 | BY9: 220
A10: 8 | B10: 54.81 | C10: 51.39 | D10: 212.26 | E10: 461.78 | F10: 153.52 | G10: 130.81 | H10: 147.58 | I10: 186.43 | S10: 60.49 | T10: 50 | U10: 234.05 | V10: 250 | W10: 139.53 | X10: 127.39 | Y10: 128.07 | Z10: 186.28 | AJ10: 60.8 | AK10: 49.87 | AL10: 234.04 | AM10: 250 | AN10: 139.48 | AO10: 127.32 | AP10: 127.94 | AQ10: 186.01 | BA10: 59.01 | BB10: 53 | BC10: 248.95 | BD10: 501.79 | BE10: 158.43 | BF10: 114.22 | BG10: 125.96 | BH10: 177.5 | BR10: 71.56 | BS10: 59.58 | BT10: 256.28 | BU10: 518.48 | BV10: 182.1 | BW10: 151.66 | BX10: 153.68 | BY10: 215.56
A11: 9 | B11: 54 | C11: 50.18 | D11: 203.09 | E11: 450.66 | F11: 150.68 | G11: 128.14 | H11: 143.5 | I11: 182.34 | S11: 59.83 | T11: 49.26 | U11: 228.86 | V11: 247.45 | W11: 137.74 | X11: 125 | Y11: 125.22 | Z11: 183.4 | AJ11: 59.97 | AK11: 49.16 | AL11: 228.86 | AM11: 247.37 | AN11: 137.67 | AO11: 124.98 | AP11: 125.21 | AQ11: 183.13 | BA11: 57.61 | BB11: 52.03 | BC11: 240 | BD11: 485 | BE11: 154.66 | BF11: 111.8 | BG11: 123.82 | BH11: 173.97 | BR11: 70.69 | BS11: 58.35 | BT11: 250.01 | BU11: 502.69 | BV11: 179.66 | BW11: 148.97 | BX11: 151.78 | BY11: 212.46
A12: 10 | B12: 53.2 | C12: 49.2 | D12: 197.53 | E12: 439.44 | F12: 147.16 | G12: 125.25 | H12: 140.93 | I12: 178.76 | S12: 59.21 | T12: 48.61 | U12: 223 | V12: 243.47 | W12: 135.86 | X12: 122.75 | Y12: 123.52 | Z12: 180.24 | AJ12: 59.38 | AK12: 48.42 | AL12: 223 | AM12: 243.47 | AN12: 135.72 | AO12: 122.58 | AP12: 123.49 | AQ12: 180.04 | BA12: 56.42 | BB12: 50.9 | BC12: 230.25 | BD12: 472.39 | BE12: 151.97 | BF12: 109.88 | BG12: 121.32 | BH12: 170.37 | BR12: 69.73 | BS12: 57.26 | BT12: 243.02 | BU12: 493.05 | BV12: 175.46 | BW12: 145.72 | BX12: 150.05 | BY12: 208.34
A13: 11 | B13: 52.74 | C13: 48.27 | D13: 190 | E13: 428.82 | F13: 144.8 | G13: 123.01 | H13: 137.73 | I13: 175.55 | S13: 58.8 | T13: 48 | U13: 218.3 | V13: 240 | W13: 134.1 | X13: 120.75 | Y13: 121.29 | Z13: 176.59 | AJ13: 58.9 | AK13: 47.86 | AL13: 218.3 | AM13: 240 | AN13: 134 | AO13: 120.72 | AP13: 121.16 | AQ13: 176.48 | BA13: 55.39 | BB13: 50 | BC13: 223.24 | BD13: 461.16 | BE13: 149.68 | BF13: 108.05 | BG13: 119.39 | BH13: 167.4 | BR13: 68.65 | BS13: 56.05 | BT13: 236.88 | BU13: 480.21 | BV13: 172.81 | BW13: 143.4 | BX13: 148.95 | BY13: 205.19
... A102: 100 | B102: -90.01 | C102: -83.94 | D102: -69 | E102: -19.04 | F102: -500 | G102: -135.45 | H102: -250.32 | I102: -499 | S102: 0.03 | T102: 1.02 | U102: 0.01 | V102: 0 | W102: 0 | X102: -2 | Y102: -15 | Z102: -9.82 | AJ102: 0.01 | AK102: 1.02 | AL102: 0 | AM102: 0 | AN102: 0 | AO102: -2 | AP102: -5 | AQ102: -9.82 | BA102: -24.92 | BB102: -75.82 | BC102: -66.18 | BD102: -1.44 | BE102: -134.94 | BF102: -87.29 | BG102: -118.01 | BH102: -496.86 | BR102: 1 | BS102: 0 | BT102: 3 | BU102: 10 | BV102: 2.36 | BW102: 0.1 | BX102: 0 | BY102: 0

Sheet Fig5_Capture
A1: technology | B1: DE_2019 | C1: DE_2020 | D1: DE_2021 | E1: DE_2022 | F1: DE_2023 | G1: DE_2024 | H1: DE_2025 | I1: DE_2026 | J1: DE_2027 | K1: DE_2028 | L1: DE_2029 | M1: DE_2030 | N1: DE_2031 | O1: DE_2032 | P1: DE_2033 | Q1: DE_2034 | R1: DE_2035 | S1: ES_2019 | T1: ES_2020 | U1: ES_2021 | V1: ES_2022 | W1: ES_2023 | X1: ES_2024 | Y1: ES_2025 | Z1: ES_2026 | AA1: ES_2027 | AB1: ES_2028 | AC1: ES_2029 | AD1: ES_2030 | AE1: ES_2031 | AF1: ES_2032 | AG1: ES_2033 | AH1: ES_2034 | AI1: ES_2035 | AJ1: PT_2019 | AK1: PT_2020 | AL1: PT_2021 | AM1: PT_2022 | AN1: PT_2023 | AO1: PT_2024 | AP1: PT_2025 | AQ1: PT_2026 | AR1: PT_2027 | AS1: PT_2028 | AT1: PT_2029 | AU1: PT_2030 | AV1: PT_2031 | AW1: PT_2032 | AX1: PT_2033 | AY1: PT_2034 | AZ1: PT_2035 | BA1: FR_2019 | BB1: FR_2020 | BC1: FR_2021 | BD1: FR_2022 | BE1: FR_2023 | BF1: FR_2024 | BG1: FR_2025 | BH1: FR_2026 | BI1: FR_2027 | BJ1: FR_2028 | BK1: FR_2029 | BL1: FR_2030 | BM1: FR_2031 | BN1: FR_2032 | BO1: FR_2033 | BP1: FR_2034 | BQ1: FR_2035 | BR1: IT_2019 | BS1: IT_2020 | BT1: IT_2021 | BU1: IT_2022 | BV1: IT_2023 | BW1: IT_2024 | BX1: IT_2025 | BY1: IT_2026 | BZ1: IT_2027 | CA1: IT_2028 | CB1: IT_2029 | CC1: IT_2030 | CD1: IT_2031 | CE1: IT_2032 | CF1: IT_2033 | CG1: IT_2034 | CH1: IT_2035
A2: Solar | B2: -7.33 | C2: -19.56 | D2: -22.09 | E2: -5.59 | F2: -24.16 | G2: -41.12 | H2: -48.44 | I2: -46.74 | S2: 1.89 | T2: -3.13 | U2: -8.53 | V2: -9.92 | W2: -16.44 | X2: -32.74 | Y2: -44.59 | Z2: -48.33 | AJ2: 1.86 | AK2: -2.22 | AL2: -4.04 | AM2: -10.08 | AN2: -17.28 | AO2: -32.7 | AP2: -46.6 | AQ2: -49.22 | BA2: -4.29 | BB2: -7.28 | BC2: -13.64 | BD2: 5.67 | BE2: -13.69 | BF2: -32.35 | BG2: -40.95 | BH2: -44.44 | BR2: -3.14 | BS2: -11.06 | BT2: -13.22 | BU2: 1.2 | BV2: -12.83 | BW2: -11.13 | BX2: -17.07 | BY2: -15.65
A3: Onshore wind | B3: -14.2 | C3: -19.34 | D3: -16.64 | E3: -28.51 | F3: -17.43 | G3: -17.78 | H3: -13.4 | I3: -12.11 | S3: -4.25 | T3: -4.64 | U3: -7.28 | V3: -4.17 | W3: -12.51 | X3: -12.01 | Y3: -3.21 | Z3: -8.15 | AJ3: -5.91 | AK3: -5 | AL3: -1.64 | AM3: -5.54 | AN3: -13.08 | AO3: -12.95 | AP3: -8.34 | AQ3: -17.24 | BA3: -5.4 | BB3: -6.38 | BC3: -6.07 | BD3: -15.16 | BE3: -10.87 | BF3: -9.93 | BG3: -10.35 | BH3: -11.58 | BR3: -1.1 | BS3: -3.55 | BT3: 1.42 | BU3: -6.31 | BV3: -0.49 | BW3: -4.48 | BX3: -1.76 | BY3: -6.05
A4: Offshore wind | B4: -7.74 | C4: -8.62 | D4: -4.65 | E4: -17.4 | F4: -9.06 | G4: -9.05 | H4: -4.24 | I4: -6.16 | AL4: 27.21 | AM4: -6.35 | AN4: -7.71 | AO4: -10.99 | AP4: -5.42 | AQ4: -12.69 | BF4: -7.88 | BG4: -10.46 | BH4: -8.38 | BV4: -0.1 | BW4: -6.15 | BX4: -3.15 | BY4: -8.49
A5: Hydro pumped (production) | B5: 24.06 | C5: -0.24 | D5: 28.48 | E5: 27.07 | F5: 31.97 | G5: 44.68 | H5: 45.52 | I5: 48.24 | W5: 22.47 | X5: 27.55 | Y5: 41.91 | Z5: 50.13 | AJ5: 3.89 | AK5: 15.08 | AL5: 8.18 | AM5: 9.31 | AN5: 13.55 | AO5: 21.55 | AP5: 42.32 | AQ5: 39.53 | BA5: 26.39 | BB5: 28.06 | BC5: 32.5 | BD5: 20.33 | BE5: 29.25 | BF5: 48.57 | BG5: 45.9 | BH5: 37.59 | BR5: 17.04 | BS5: 28.3 | BT5: 16.54 | BU5: 24.4 | BV5: 12.6 | BW5: 14.81 | BX5: 18.29 | BY5: 22.82
A6: Hydro reservoir | B6: 11.71 | C6: 18.58 | D6: 11.18 | E6: 20.16 | F6: 16.6 | G6: 28.44 | H6: 27.45 | I6: 27.97 | S6: 1.63 | T6: 9.28 | U6: -11.12 | V6: 10.05 | W6: 6.79 | X6: 4.2 | Y6: 20.57 | Z6: 7.66 | AJ6: 0.92 | AK6: 15.14 | AL6: -6.24 | AM6: -7.7 | AN6: 2.03 | AO6: -3.17 | AP6: 25.67 | AQ6: 11.5 | BA6: 13.7 | BB6: 8.43 | BC6: -2.24 | BD6: 13.48 | BE6: 14.59 | BF6: 19.13 | BG6: 38.46 | BH6: 19.72 | BR6: 6.68 | BS6: 10.6 | BT6: -3.11 | BU6: 16.04 | BV6: 3.31 | BW6: 6.32 | BX6: 8.5 | BY6: 13.21
A7: Hydro run-of-river | B7: -0.23 | C7: -0.51 | D7: -6.69 | E7: 0.45 | F7: -1.62 | G7: -0.48 | H7: 1.06 | I7: -1.5 | S7: -0.49 | T7: -3.04 | U7: -13.44 | V7: 2.69 | W7: -2.34 | X7: -5.67 | Y7: 1.06 | Z7: -14.23 | AJ7: 1.09 | AK7: 6.86 | AL7: -23.11 | AM7: 4.47 | AN7: 6.25 | AO7: -1.33 | AP7: 15.66 | AQ7: 6.54 | BA7: 1.7 | BB7: -1.79 | BC7: -8.78 | BD7: -4.8 | BE7: 1.66 | BF7: 0.93 | BG7: 10.35 | BH7: -7.18 | BR7: 2.01 | BS7: 2.6 | BT7: -3.5 | BU7: 6.61 | BV7: -1.3 | BW7: 2.21 | BX7: 0.49 | BY7: 1.42
A8: Biomass | B8: 0.47 | C8: 0.27 | D8: 1.01 | E8: 0.08 | F8: 1.97 | G8: 2.51 | H8: 3.94 | I8: 2.56 | S8: 0.37 | T8: 1.58 | U8: 4.14 | V8: 3.19 | W8: 7.27 | X8: 4.01 | Y8: 4.68 | Z8: 6.95 | AJ8: -1.15 | AK8: 0.32 | AL8: 0.11 | AM8: 1.46 | AN8: 0.5 | AO8: -2.24 | AP8: 0.61 | AQ8: 2.63 | BA8: -0.66 | BB8: 0.23 | BC8: 0.06 | BD8: -2.22 | BE8: 1.12 | BF8: -0.1 | BG8: 4.37 | BH8: -5.91 | BR8: -0.62 | BS8: 0.06 | BT8: 0.63 | BU8: 0.54 | BV8: 1.34 | BW8: -0.11 | BX8: -1.07 | BY8: 0.94
A9: Gas | B9: 10.46 | C9: 16.74 | D9: 10.99 | E9: 9.13 | F9: 15.38 | G9: 20.94 | H9: 23.59 | I9: 13.82 | S9: 3.19 | T9: 8.21 | U9: 19.73 | V9: 4.11 | W9: 16.67 | X9: 32.97 | Y9: 23.68 | Z9: 38.56 | AJ9: 4.56 | AK9: 13.21 | AL9: 14.65 | AM9: 6.63 | AN9: 23.35 | AO9: 29.24 | AP9: 9.66 | AQ9: 0.24 | BA9: 14.88 | BB9: 18.51 | BC9: 23.49 | BD9: 4.4 | BE9: 24.73 | BF9: 42.51 | BG9: 57.27 | BH9: 41.13 | BR9: 5.91 | BS9: 10.27 | BT9: 11.72 | BU9: 6.62 | BV9: 6.8 | BW9: 9.71 | BX9: 9.11 | BY9: 9.33
A10: Lignite | B10: 8.6 | C10: 17.39 | D10: 10.31 | E10: 6.6 | F10: 15.59 | G10: 16.3 | H10: 16.68 | I10: 15.32 | S10: 29.9
A11: Hard coal | B11: 19.03 | C11: 29.81 | D11: 29.5 | E11: 15.27 | F11: 22.52 | G11: 20.64 | H11: 25.12 | I11: 17.11 | S11: 13.18 | T11: 5.31 | U11: 21.69 | V11: 4.67 | W11: 8.34 | X11: 7.79 | Y11: 16.5 | Z11: 46.35 | AJ11: 15.46 | AK11: 29.58 | AL11: -3.18 | BA11: 41.29 | BB11: 49.15 | BC11: 34.31 | BD11: 2.95 | BE11: 48.34 | BF11: 63 | BG11: 84.75 | BH11: 28.14 | BR11: 5.95 | BS11: 5.35 | BT11: 14.33 | BU11: 2.24 | BV11: 8.63 | BW11: 0.25 | BX11: 1.84 | BY11: 6.89
A12: Nuclear | B12: 1.88 | C12: 2.99 | D12: 1.1 | E12: 1.69 | F12: 19.29 | S12: 0.59 | T12: 2.55 | U12: -2.69 | V12: 0.35 | W12: 1.46 | X12: 3.52 | Y12: 6.02 | Z12: 3.79 | BA12: 2.67 | BB12: 2.41 | BC12: 1.09 | BD12: -2.89 | BE12: 2.89 | BF12: 6.9 | BG12: 8.17 | BH12: 0.4
A13: Solar | B13: -7.33 | C13: -19.56 | D13: -22.09 | E13: -5.59 | F13: -24.16 | G13: -41.12 | H13: -48.44 | I13: -46.74 | S13: 1.89 | T13: -3.13 | U13: -8.53 | V13: -9.92 | W13: -16.44 | X13: -32.74 | Y13: -44.59 | Z13: -48.33 | AJ13: 1.86 | AK13: -2.22 | AL13: -4.04 | AM13: -10.08 | AN13: -17.28 | AO13: -32.7 | AP13: -46.6 | AQ13: -49.22 | BA13: -4.29 | BB13: -7.28 | BC13: -13.64 | BD13: 5.67 | BE13: -13.69 | BF13: -32.35 | BG13: -40.95 | BH13: -44.44 | BR13: -3.14 | BS13: -11.06 | BT13: -13.22 | BU13: 1.2 | BV13: -12.83 | BW13: -11.13 | BX13: -17.07 | BY13: -15.65
A14: Onshore wind | B14: -14.2 | C14: -19.34 | D14: -16.64 | E14: -28.51 | F14: -17.43 | G14: -17.78 | H14: -13.4 | I14: -12.11 | S14: -4.25 | T14: -4.64 | U14: -7.28 | V14: -4.17 | W14: -12.51 | X14: -12.01 | Y14: -3.21 | Z14: -8.15 | AJ14: -5.91 | AK14: -5 | AL14: -1.64 | AM14: -5.54 | AN14: -13.08 | AO14: -12.95 | AP14: -8.34 | AQ14: -17.24 | BA14: -5.4 | BB14: -6.38 | BC14: -6.07 | BD14: -15.16 | BE14: -10.87 | BF14: -9.93 | BG14: -10.35 | BH14: -11.58 | BR14: -1.1 | BS14: -3.55 | BT14: 1.42 | BU14: -6.31 | BV14: -0.49 | BW14: -4.48 | BX14: -1.76 | BY14: -6.05
A15: Hydro run-of-river | B15: -0.23 | C15: -0.51 | D15: -6.69 | E15: 0.45 | F15: -1.62 | G15: -0.48 | H15: 1.06 | I15: -1.5 | S15: -0.49 | T15: -3.04 | U15: -13.44 | V15: 2.69 | W15: -2.34 | X15: -5.67 | Y15: 1.06 | Z15: -14.23 | AJ15: 1.09 | AK15: 6.86 | AL15: -23.11 | AM15: 4.47 | AN15: 6.25 | AO15: -1.33 | AP15: 15.66 | AQ15: 6.54 | BA15: 1.7 | BB15: -1.79 | BC15: -8.78 | BD15: -4.8 | BE15: 1.66 | BF15: 0.93 | BG15: 10.35 | BH15: -7.18 | BR15: 2.01 | BS15: 2.6 | BT15: -3.5 | BU15: 6.61 | BV15: -1.3 | BW15: 2.21 | BX15: 0.49 | BY15: 1.42
A16: Hydro reservoir | B16: 11.71 | C16: 18.58 | D16: 11.18 | E16: 20.16 | F16: 16.6 | G16: 28.44 | H16: 27.45 | I16: 27.97 | S16: 1.63 | T16: 9.28 | U16: -11.12 | V16: 10.05 | W16: 6.79 | X16: 4.2 | Y16: 20.57 | Z16: 7.66 | AJ16: 0.92 | AK16: 15.14 | AL16: -6.24 | AM16: -7.7 | AN16: 2.03 | AO16: -3.17 | AP16: 25.67 | AQ16: 11.5 | BA16: 13.7 | BB16: 8.43 | BC16: -2.24 | BD16: 13.48 | BE16: 14.59 | BF16: 19.13 | BG16: 38.46 | BH16: 19.72 | BR16: 6.68 | BS16: 10.6 | BT16: -3.11 | BU16: 16.04 | BV16: 3.31 | BW16: 6.32 | BX16: 8.5 | BY16: 13.21
A17: Hydro pumped (production) | B17: 24.06 | C17: -0.24 | D17: 28.48 | E17: 27.07 | F17: 31.97 | G17: 44.68 | H17: 45.52 | I17: 48.24 | W17: 22.47 | X17: 27.55 | Y17: 41.91 | Z17: 50.13 | AJ17: 3.89 | AK17: 15.08 | AL17: 8.18 | AM17: 9.31 | AN17: 13.55 | AO17: 21.55 | AP17: 42.32 | AQ17: 39.53 | BA17: 26.39 | BB17: 28.06 | BC17: 32.5 | BD17: 20.33 | BE17: 29.25 | BF17: 48.57 | BG17: 45.9 | BH17: 37.59 | BR17: 17.04 | BS17: 28.3 | BT17: 16.54 | BU17: 24.4 | BV17: 12.6 | BW17: 14.81 | BX17: 18.29 | BY17: 22.82
A18: Biomass | B18: 0.47 | C18: 0.27 | D18: 1.01 | E18: 0.08 | F18: 1.97 | G18: 2.51 | H18: 3.94 | I18: 2.56 | S18: 0.37 | T18: 1.58 | U18: 4.14 | V18: 3.19 | W18: 7.27 | X18: 4.01 | Y18: 4.68 | Z18: 6.95 | AJ18: -1.15 | AK18: 0.32 | AL18: 0.11 | AM18: 1.46 | AN18: 0.5 | AO18: -2.24 | AP18: 0.61 | AQ18: 2.63 | BA18: -0.66 | BB18: 0.23 | BC18: 0.06 | BD18: -2.22 | BE18: 1.12 | BF18: -0.1 | BG18: 4.37 | BH18: -5.91 | BR18: -0.62 | BS18: 0.06 | BT18: 0.63 | BU18: 0.54 | BV18: 1.34 | BW18: -0.11 | BX18: -1.07 | BY18: 0.94
A19: Gas | B19: 10.46 | C19: 16.74 | D19: 10.99 | E19: 9.13 | F19: 15.38 | G19: 20.94 | H19: 23.59 | I19: 13.82 | S19: 3.19 | T19: 8.21 | U19: 19.73 | V19: 4.11 | W19: 16.67 | X19: 32.97 | Y19: 23.68 | Z19: 38.56 | AJ19: 4.56 | AK19: 13.21 | AL19: 14.65 | AM19: 6.63 | AN19: 23.35 | AO19: 29.24 | AP19: 9.66 | AQ19: 0.24 | BA19: 14.88 | BB19: 18.51 | BC19: 23.49 | BD19: 4.4 | BE19: 24.73 | BF19: 42.51 | BG19: 57.27 | BH19: 41.13 | BR19: 5.91 | BS19: 10.27 | BT19: 11.72 | BU19: 6.62 | BV19: 6.8 | BW19: 9.71 | BX19: 9.11 | BY19: 9.33
A20: Oil & other fossil | B20: 1.26 | C20: 1.83 | D20: -0.77 | E20: 1.61 | F20: 0.36 | G20: 1.86 | H20: 3.92 | I20: 1.02 | S20: 2.71 | T20: 1.65 | U20: 5.72 | V20: 10.37 | W20: 13.39 | X20: 6.34 | Y20: 14.96 | Z20: 13.9 | BA20: 7.68 | BB20: 7.03 | BC20: 13.95 | BD20: 8.27 | BE20: 10.79 | BF20: 7.07 | BG20: 23.86 | BH20: 30.08 | BR20: 2.94 | BS20: 11.56 | BT20: 25.18 | BU20: 8.03 | BV20: 18.9 | BW20: 13.96 | BX20: -1.27 | BY20: 15.83
A21: Waste | B21: 0.07 | C21: 1.02 | D21: 2.01 | E21: -0.38 | F21: 0.13 | G21: 0.45 | H21: 1.15 | I21: 1.98 | S21: 0.63 | T21: 1.76 | U21: -0.11 | V21: 3.33 | W21: 2.91 | X21: 4.37 | Y21: 6.04 | Z21: 9.94 | BA21: 1.56 | BB21: 1.69 | BC21: 0.42 | BD21: -1.18 | BE21: 2.09 | BF21: 4.83 | BG21: -1.56 | BH21: 1.27 | BR21: 0.49 | BS21: 0.79 | BT21: -3.5 | BU21: 1.78 | BV21: -6.6 | BW21: -0.45 | BX21: -1.65 | BY21: -10.9
A22: Geothermal | B22: 0.45 | C22: 0.36 | D22: 4.76 | E22: -3.8 | F22: 1.59 | G22: 2.11 | H22: 3.96 | I22: -0.59 | BR22: 0 | BS22: -0.14 | BT22: -0.23 | BU22: -0.41 | BV22: 0.02 | BW22: -2.57 | BX22: -3.13 | BY22: 1.39
A23: Marine
A24: Other renewable | B24: 1.6 | C24: 2.2 | D24: 4.14 | E24: -2.15 | F24: 4.08 | G24: 0.89 | H24: 1.71 | I24: -0.94 | S24: 0.64 | T24: 0.66 | U24: 1.14 | V24: 2.62 | W24: 1.54 | X24: 1.86 | Y24: 4.39 | Z24: 1.61 | BX24: 24.01
A25: Other | B25: 2.92 | C25: 4.22 | D25: 3.51 | E25: -0.42 | F25: 5.27 | G25: 6.27 | H25: 7.22 | I25: 2.23 | S25: 1.12 | T25: 0.43 | U25: -0.04 | V25: -0.66 | W25: 2.82 | X25: 19.33 | Y25: 3.68 | Z25: 17.69 | AJ25: 3.01 | AK25: 0.45 | AL25: -1.86 | AM25: -0.18 | AN25: 2.52 | AO25: 0.4 | AP25: 3.31 | AQ25: 0.42 | BH25: 48.41 | BR25: 3.54 | BS25: 4.59 | BT25: 3.11 | BU25: 2.17 | BV25: 4.68 | BW25: 3.09 | BX25: 3.05 | BY25: 3.12

Sheet Fig6_MinMax
A1: doy | B1: DE_2019_min | C1: DE_2020_min | D1: DE_2021_min | E1: DE_2022_min | F1: DE_2023_min | G1: DE_2024_min | H1: DE_2025_min | I1: DE_2026_min | J1: DE_2027_min | K1: DE_2028_min | L1: DE_2029_min | M1: DE_2030_min | N1: DE_2031_min | O1: DE_2032_min | P1: DE_2033_min | Q1: DE_2034_min | R1: DE_2035_min | S1: ES_2019_min | T1: ES_2020_min | U1: ES_2021_min | V1: ES_2022_min | W1: ES_2023_min | X1: ES_2024_min | Y1: ES_2025_min | Z1: ES_2026_min | AA1: ES_2027_min | AB1: ES_2028_min | AC1: ES_2029_min | AD1: ES_2030_min | AE1: ES_2031_min | AF1: ES_2032_min | AG1: ES_2033_min | AH1: ES_2034_min | AI1: ES_2035_min | AJ1: PT_2019_min | AK1: PT_2020_min | AL1: PT_2021_min | AM1: PT_2022_min | AN1: PT_2023_min | AO1: PT_2024_min | AP1: PT_2025_min | AQ1: PT_2026_min | AR1: PT_2027_min | AS1: PT_2028_min | AT1: PT_2029_min | AU1: PT_2030_min | AV1: PT_2031_min | AW1: PT_2032_min | AX1: PT_2033_min | AY1: PT_2034_min | AZ1: PT_2035_min | BA1: FR_2019_min | BB1: FR_2020_min | BC1: FR_2021_min | BD1: FR_2022_min | BE1: FR_2023_min | BF1: FR_2024_min | BG1: FR_2025_min | BH1: FR_2026_min | BI1: FR_2027_min | BJ1: FR_2028_min | BK1: FR_2029_min | BL1: FR_2030_min | BM1: FR_2031_min | BN1: FR_2032_min | BO1: FR_2033_min | BP1: FR_2034_min | BQ1: FR_2035_min | BR1: IT_2019_min | BS1: IT_2020_min | BT1: IT_2021_min | BU1: IT_2022_min | BV1: IT_2023_min | BW1: IT_2024_min | BX1: IT_2025_min | BY1: IT_2026_min | BZ1: IT_2027_min | CA1: IT_2028_min | CB1: IT_2029_min | CC1: IT_2030_min | CD1: IT_2031_min | CE1: IT_2032_min | CF1: IT_2033_min | CG1: IT_2034_min | CH1: IT_2035_min | CI1: DE_2019_max | CJ1: DE_2020_max | CK1: DE_2021_max | CL1: DE_2022_max | CM1: DE_2023_max | CN1: DE_2024_max | CO1: DE_2025_max | CP1: DE_2026_max | CQ1: DE_2027_max | CR1: DE_2028_max | CS1: DE_2029_max | CT1: DE_2030_max | CU1: DE_2031_max | CV1: DE_2032_max | CW1: DE_2033_max | CX1: DE_2034_max | CY1: DE_2035_max | CZ1: ES_2019_max | DA1: ES_2020_max | DB1: ES_2021_max | DC1: ES_2022_max | DD1: ES_2023_max | DE1: ES_2024_max | DF1: ES_2025_max | DG1: ES_2026_max | DH1: ES_2027_max | DI1: ES_2028_max | DJ1: ES_2029_max | DK1: ES_2030_max | DL1: ES_2031_max | DM1: ES_2032_max | DN1: ES_2033_max | DO1: ES_2034_max | DP1: ES_2035_max | DQ1: PT_2019_max | DR1: PT_2020_max | DS1: PT_2021_max | DT1: PT_2022_max | DU1: PT_2023_max | DV1: PT_2024_max | DW1: PT_2025_max | DX1: PT_2026_max | DY1: PT_2027_max | DZ1: PT_2028_max | EA1: PT_2029_max | EB1: PT_2030_max | EC1: PT_2031_max | ED1: PT_2032_max | EE1: PT_2033_max | EF1: PT_2034_max | EG1: PT_2035_max | EH1: FR_2019_max | EI1: FR_2020_max | EJ1: FR_2021_max | EK1: FR_2022_max | EL1: FR_2023_max | EM1: FR_2024_max | EN1: FR_2025_max | EO1: FR_2026_max | EP1: FR_2027_max | EQ1: FR_2028_max | ER1: FR_2029_max | ES1: FR_2030_max | ET1: FR_2031_max | EU1: FR_2032_max | EV1: FR_2033_max | EW1: FR_2034_max | EX1: FR_2035_max | EY1: IT_2019_max | EZ1: IT_2020_max | FA1: IT_2021_max | FB1: IT_2022_max | FC1: IT_2023_max | FD1: IT_2024_max | FE1: IT_2025_max | FF1: IT_2026_max | FG1: IT_2027_max | FH1: IT_2028_max | FI1: IT_2029_max | FJ1: IT_2030_max | FK1: IT_2031_max | FL1: IT_2032_max | FM1: IT_2033_max | FN1: IT_2034_max | FO1: IT_2035_max | FP1: DE_2019_mean | FQ1: DE_2020_mean | FR1: DE_2021_mean | FS1: DE_2022_mean | FT1: DE_2023_mean | FU1: DE_2024_mean | FV1: DE_2025_mean | FW1: DE_2026_mean | FX1: DE_2027_mean | FY1: DE_2028_mean | FZ1: DE_2029_mean | GA1: DE_2030_mean | GB1: DE_2031_mean | GC1: DE_2032_mean | GD1: DE_2033_mean | GE1: DE_2034_mean | GF1: DE_2035_mean | GG1: ES_2019_mean | GH1: ES_2020_mean | GI1: ES_2021_mean | GJ1: ES_2022_mean | GK1: ES_2023_mean | GL1: ES_2024_mean | GM1: ES_2025_mean | GN1: ES_2026_mean | GO1: ES_2027_mean | GP1: ES_2028_mean | GQ1: ES_2029_mean | GR1: ES_2030_mean | GS1: ES_2031_mean | GT1: ES_2032_mean | GU1: ES_2033_mean | GV1: ES_2034_mean | GW1: ES_2035_mean | GX1: PT_2019_mean | GY1: PT_2020_mean | GZ1: PT_2021_mean | HA1: PT_2022_mean | HB1: PT_2023_mean | HC1: PT_2024_mean | HD1: PT_2025_mean | HE1: PT_2026_mean | HF1: PT_2027_mean | HG1: PT_2028_mean | HH1: PT_2029_mean | HI1: PT_2030_mean | HJ1: PT_2031_mean | HK1: PT_2032_mean | HL1: PT_2033_mean | HM1: PT_2034_mean | HN1: PT_2035_mean | HO1: FR_2019_mean | HP1: FR_2020_mean | HQ1: FR_2021_mean | HR1: FR_2022_mean | HS1: FR_2023_mean | HT1: FR_2024_mean | HU1: FR_2025_mean | HV1: FR_2026_mean | HW1: FR_2027_mean | HX1: FR_2028_mean | HY1: FR_2029_mean | HZ1: FR_2030_mean | IA1: FR_2031_mean | IB1: FR_2032_mean | IC1: FR_2033_mean | ID1: FR_2034_mean | IE1: FR_2035_mean | IF1: IT_2019_mean | IG1: IT_2020_mean | IH1: IT_2021_mean | II1: IT_2022_mean | IJ1: IT_2023_mean | IK1: IT_2024_mean | IL1: IT_2025_mean | IM1: IT_2026_mean | IN1: IT_2027_mean | IO1: IT_2028_mean | IP1: IT_2029_mean | IQ1: IT_2030_mean | IR1: IT_2031_mean | IS1: IT_2032_mean | IT1: IT_2033_mean | IU1: IT_2034_mean | IV1: IT_2035_mean
A2: 1 | B2: -33.57 | C2: 30 | D2: 39.63 | E2: 37.67 | F2: -5.4 | G2: -0.05 | H2: -1.01 | I2: -0.01 | S2: 55.47 | T2: 30 | U2: 35.5 | V2: 70.05 | W2: 0 | X2: 1.73 | Y2: 10.68 | Z2: 52.8 | AJ2: 55.47 | AK2: 30 | AL2: 35.5 | AM2: 70.05 | AN2: 0 | AO2: 1.73 | AP2: 20.59 | AQ2: 52.8 | BA2: 20.9 | BB2: 30 | BC2: 39.63 | BD2: 37.67 | BE2: -4.37 | BF2: -0.04 | BG2: 5.9 | BH2: 20.68 | BR2: 20 | BS2: 30 | BT2: 39.63 | BU2: 67.99 | BV2: 165.89 | BW2: 85 | BX2: 116.68 | BY2: 92.76 | CI2: 10.07 | CJ2: 44.05 | CK2: 60.61 | CL2: 149.97 | CM2: 57.91 | CN2: 58 | CO2: 10.05 | CP2: 42.4 | CZ2: 68.07 | DA2: 46.16 | DB2: 57.4 | DC2: 190.81 | DD2: 61.38 | DE2: 60.9 | DF2: 152.99 | DG2: 106.78 | DQ2: 68.07 | DR2: 46.16 | DS2: 57.4 | DT2: 190.81 | DU2: 61.38 | DV2: 60.9 | DW2: 152.99 | DX2: 106.78 | EH2: 65.56 | EI2: 46.16 | EJ2: 60.61 | EK2: 149.97 | EL2: 61.38 | EM2: 54.97 | EN2: 50.14 | EO2: 82.33 | EY2: 66.25 | EZ2: 48.99 | FA2: 60.61 | FB2: 214.66 | FC2: 243.42 | FD2: 132 | FE2: 174 | FF2: 120.41 | FP2: -6.88 | FQ2: 34.69 | FR2: 48.22 | FS2: 82.87 | FT2: 17.54 | FU2: 17.45 | FV2: 0.97 | FW2: 7.73 | GG2: 63.24 | GH2: 35.27 | GI2: 42.34 | GJ2: 122.1 | GK2: 9.26 | GL2: 35.18 | GM2: 101.04 | GN2: 80.68 | GX2: 63.24 | GY2: 35.27 | GZ2: 42.34 | HA2: 122.1 | HB2: 9.26 | HC2: 36.7 | HD2: 103.73 | HE2: 80.68 | HO2: 41.33 | HP2: 34.94 | HQ2: 48.22 | HR2: 85.75 | HS2: 17.47 | HT2: 13.94 | HU2: 23.74 | HV2: 46.67 | IF2: 44.19 | IG2: 35.53 | IH2: 47.99 | II2: 149.9 | IJ2: 192.78 | IK2: 105.65 | IL2: 140.41 | IM2: 106.14
A3: 2 | B3: -48.93 | C3: 21.47 | D3: 37.55 | E3: 0.31 | F3: 44.09 | G3: -0.08 | H3: 1.56 | I3: 0.24 | S3: 45.24 | T3: 28.42 | U3: 37.55 | V3: 103.7 | W3: 42 | X3: 3.99 | Y3: 99.82 | Z3: 55.01 | AJ3: 51.09 | AK3: 28.42 | AL3: 37.55 | AM3: 109.8 | AN3: 42 | AO3: 6.8 | AP3: 101.88 | AQ3: 55.01 | BA3: 25.84 | BB3: 28.42 | BC3: 37.55 | BD3: 2.71 | BE3: 42.75 | BF3: 0.01 | BG3: 40.15 | BH3: 17.31 | BR3: 36 | BS3: 28.79 | BT3: 30.55 | BU3: 100 | BV3: 170.77 | BW3: 82.5 | BX3: 115.78 | BY3: 90 | CI3: 62.11 | CJ3: 46.72 | CK3: 63.08 | CL3: 70.09 | CM3: 174.74 | CN3: 83.46 | CO3: 152.94 | CP3: 89.15 | CZ3: 69.3 | DA3: 46.72 | DB3: 60.43 | DC3: 209.1 | DD3: 174.74 | DE3: 62.45 | DF3: 161.1 | DG3: 107 | DQ3: 69.3 | DR3: 46.72 | DS3: 60.43 | DT3: 209.1 | DU3: 174.74 | DV3: 62.45 | DW3: 161.1 | DX3: 107 | EH3: 69.3 | EI3: 46.72 | EJ3: 63.08 | EK3: 70.09 | EL3: 174.74 | EM3: 62.45 | EN3: 153.4 | EO3: 103.6 | EY3: 74.6 | EZ3: 61.96 | FA3: 65.72 | FB3: 245 | FC3: 262 | FD3: 130 | FE3: 170 | FF3: 120.9 | FP3: 29.1 | FQ3: 38.29 | FR3: 50.54 | FS3: 44.99 | FT3: 126.82 | FU3: 51.8 | FV3: 96.95 | FW3: 57.63 | GG3: 60.55 | GH3: 39.85 | GI3: 48.7 | GJ3: 138.98 | GK3: 115.41 | GL3: 39.62 | GM3: 133.37 | GN3: 82.93 | GX3: 61.6 | GY3: 39.85 | GZ3: 48.7 | HA3: 139.76 | HB3: 112.94 | HC3: 40.49 | HD3: 133.72 | HE3: 82.93 | HO3: 54.02 | HP3: 39.32 | HQ3: 50.54 | HR3: 46.85 | HS3: 127.44 | HT3: 35.43 | HU3: 110.35 | HV3: 70.27 | IF3: 58.81 | IG3: 45.77 | IH3: 51.23 | II3: 166.21 | IJ3: 201.34 | IK3: 106.34 | IL3: 138.76 | IM3: 104.85
A4: 3 | B4: 43.88 | C4: 0.14 | D4: 27.39 | E4: -1.05 | F4: 80.89 | G4: -1.38 | H4: 69.94 | I4: 73.02 | S4: 50.2 | T4: 29.74 | U4: 35.5 | V4: 100.36 | W4: 113.63 | X4: 2.21 | Y4: 88.46 | Z4: 73.94 | AJ4: 50.2 | AK4: 29.74 | AL4: 37.45 | AM4: 100.36 | AN4: 113.63 | AO4: 2.21 | AP4: 90.01 | AQ4: 73.94 | BA4: 43.88 | BB4: 22.56 | BC4: 35.5 | BD4: 0.06 | BE4: 82.03 | BF4: -0.05 | BG4: 84.06 | BH4: 73.94 | BR4: 40.42 | BS4: 28.5 | BT4: 35.5 | BU4: 83.27 | BV4: 113.63 | BW4: 40 | BX4: 97 | BY4: 89.94 | CI4: 69.55 | CJ4: 41.35 | CK4: 52.56 | CL4: 148.49 | CM4: 171.18 | CN4: 82.97 | CO4: 116.66 | CP4: 110.82 | CZ4: 71.1 | DA4: 47.23 | DB4: 61.09 | DC4: 189.26 | DD4: 171.18 | DE4: 113.26 | DF4: 151.25 | DG4: 108.09 | DQ4: 71.1 | DR4: 47.23 | DS4: 61.09 | DT4: 189.26 | DU4: 169.01 | DV4: 113.26 | DW4: 151.25 | DX4: 108.09 | EH4: 73.43 | EI4: 45.2 | EJ4: 61.09 | EK4: 180.36 | EL4: 171.23 | EM4: 85.07 | EN4: 144.48 | EO4: 110.91 | EY4: 74.53 | EZ4: 58.13 | FA4: 62.86 | FB4: 305.47 | FC4: 200.38 | FD4: 115.81 | FE4: 152 | FF4: 121.2 | FP4: 58.04 | FQ4: 26.17 | FR4: 37.92 | FS4: 80.42 | FT4: 143.91 | FU4: 47.61 | FV4: 89.56 | FW4: 89.03 | GG4: 64.23 | GH4: 39.76 | GI4: 47.1 | GJ4: 148.16 | GK4: 138.37 | GL4: 58.57 | GM4: 121.82 | GN4: 88.74 | GX4: 64.18 | GY4: 39.76 | GZ4: 47.33 | HA4: 148.16 | HB4: 136.44 | HC4: 59.42 | HD4: 122.08 | HE4: 88.74 | HO4: 61.6 | HP4: 36.95 | HQ4: 47.27 | HR4: 97.24 | HS4: 144.05 | HT4: 48.44 | HU4: 115.91 | HV4: 89.35 | IF4: 60.06 | IG4: 44.17 | IH4: 47.93 | II4: 194.66 | IJ4: 172.69 | IK4: 93.62 | IL4: 127.2 | IM4: 104.22
